Traceback (most recent call last):
  File "/Users/kyamauch/opt/miniconda3/envs/napari-tutorial/lib/python3.9/site-packages/jupyter_cache/executors/utils.py", line 51, in single_nb_execution
    executenb(
  File "/Users/kyamauch/opt/miniconda3/envs/napari-tutorial/lib/python3.9/site-packages/nbclient/client.py", line 1117, in execute
    return NotebookClient(nb=nb, resources=resources, km=km, **kwargs).execute()
  File "/Users/kyamauch/opt/miniconda3/envs/napari-tutorial/lib/python3.9/site-packages/nbclient/util.py", line 78, in wrapped
    return just_run(coro(*args, **kwargs))
  File "/Users/kyamauch/opt/miniconda3/envs/napari-tutorial/lib/python3.9/site-packages/nbclient/util.py", line 57, in just_run
    return loop.run_until_complete(coro)
  File "/Users/kyamauch/opt/miniconda3/envs/napari-tutorial/lib/python3.9/asyncio/base_events.py", line 642, in run_until_complete
    return future.result()
  File "/Users/kyamauch/opt/miniconda3/envs/napari-tutorial/lib/python3.9/site-packages/nbclient/client.py", line 558, in async_execute
    await self.async_execute_cell(
  File "/Users/kyamauch/opt/miniconda3/envs/napari-tutorial/lib/python3.9/site-packages/nbclient/client.py", line 862, in async_execute_cell
    self._check_raise_for_error(cell, exec_reply)
  File "/Users/kyamauch/opt/miniconda3/envs/napari-tutorial/lib/python3.9/site-packages/nbclient/client.py", line 765, in _check_raise_for_error
    raise CellExecutionError.from_cell_and_msg(cell, exec_reply_content)
nbclient.exceptions.CellExecutionError: An error occurred while executing the following cell:
------------------
from matplotlib import pyplot as plt


# print the median area
median_area = np.median(rp_table['area'])
print(f'median area: {median_area} px')

# plot a histogram of the areas
plt.hist(rp_table['area']);
plt.xlabel('nucleus area', fontsize=20);
plt.ylabel('count', fontsize=20);
plt.show();
------------------

[0;31m---------------------------------------------------------------------------[0m
[0;31mNameError[0m                                 Traceback (most recent call last)
[0;32m/var/folders/hd/p540nk9s5cl9tcwdzjg2flnh0000gr/T/ipykernel_76558/747095133.py[0m in [0;36m<module>[0;34m[0m
[1;32m      3[0m [0;34m[0m[0m
[1;32m      4[0m [0;31m# print the median area[0m[0;34m[0m[0;34m[0m[0;34m[0m[0m
[0;32m----> 5[0;31m [0mmedian_area[0m [0;34m=[0m [0mnp[0m[0;34m.[0m[0mmedian[0m[0;34m([0m[0mrp_table[0m[0;34m[[0m[0;34m'area'[0m[0;34m][0m[0;34m)[0m[0;34m[0m[0;34m[0m[0m
[0m[1;32m      6[0m [0mprint[0m[0;34m([0m[0;34mf'median area: {median_area} px'[0m[0;34m)[0m[0;34m[0m[0;34m[0m[0m
[1;32m      7[0m [0;34m[0m[0m

[0;31mNameError[0m: name 'np' is not defined
NameError: name 'np' is not defined

